<?xml version="1.0" ?>
<!-- =================================================================================== -->
<!-- |    This document was autogenerated by xacro from xacro/ur10_robot.urdf.xacro    | -->
<!-- |    EDITING THIS FILE BY HAND IS NOT RECOMMENDED                                 | -->
<!-- =================================================================================== -->
<robot name="ur10_robotis_d435">
  <!--
  Author: Kelsey Hawkins
  Contributers: Jimmy Da Silva, Ajit Krisshna N L, Muhammad Asif Rana
-->
  <!-- measured from model -->
  <link name="world"/>
  <joint name="fied_world" type="fixed">
    <parent link="world" />
    <child link="base_link" />
  </joint>
  <link name="base_link">
    <visual>
      <geometry>
        <mesh filename="package://ur10/ur10/visual/base.dae"/>
      </geometry>
      <material name="LightGrey">
        <color rgba="0.7 0.7 0.7 1.0"/>
      </material>
    </visual>
    <collision>
      <geometry>
        <mesh filename="package://ur10/ur10/collision/base.stl"/>
      </geometry>
    </collision>
    <inertial>
      <mass value="4.0"/>
      <origin rpy="0 0 0" xyz="0.0 0.0 0.0"/>
      <inertia ixx="0.0061063308908" ixy="0.0" ixz="0.0" iyy="0.0061063308908" iyz="0.0" izz="0.01125"/>
    </inertial>
  </link>
  <joint name="shoulder_pan_joint" type="revolute">
    <parent link="base_link"/>
    <child link="shoulder_link"/>
    <origin rpy="0.0 0.0 0.0" xyz="0.0 0.0 0.1273"/>
    <axis xyz="0 0 1"/>
    <limit effort="330.0" lower="-6.283185307179586" upper="6.283185307179586" velocity="2.16"/>
    <dynamics damping="0.0" friction="0.0"/>
  </joint>
  <link name="shoulder_link">
    <visual>
      <geometry>
        <mesh filename="package://ur10/ur10/visual/shoulder.dae"/>
      </geometry>
      <material name="LightGrey">
        <color rgba="0.7 0.7 0.7 1.0"/>
      </material>
    </visual>
    <collision>
      <geometry>
        <mesh filename="package://ur10/ur10/collision/shoulder.stl"/>
      </geometry>
    </collision>
    <inertial>
      <mass value="7.778"/>
      <origin rpy="0 0 0" xyz="0.0 0.0 0.0"/>
      <inertia ixx="0.03147431257693659" ixy="0.0" ixz="0.0" iyy="0.03147431257693659" iyz="0.0" izz="0.021875624999999996"/>
    </inertial>
  </link>
  <joint name="shoulder_lift_joint" type="revolute">
    <parent link="shoulder_link"/>
    <child link="upper_arm_link"/>
    <origin rpy="0.0 1.5707963267948966 0.0" xyz="0.0 0.220941 0.0"/>
    <axis xyz="0 1 0"/>
    <limit effort="330.0" lower="-6.283185307179586" upper="6.283185307179586" velocity="2.16"/>
    <dynamics damping="0.0" friction="0.0"/>
  </joint>
  <link name="upper_arm_link">
    <visual>
      <geometry>
        <mesh filename="package://ur10/ur10/visual/upperarm.dae"/>
      </geometry>
      <material name="LightGrey">
        <color rgba="0.7 0.7 0.7 1.0"/>
      </material>
    </visual>
    <collision>
      <geometry>
        <mesh filename="package://ur10/ur10/collision/upperarm.stl"/>
      </geometry>
    </collision>
    <inertial>
      <mass value="12.93"/>
      <origin rpy="0 0 0" xyz="0.0 -0.045 0.306"/>
      <inertia ixx="0.42175380379841093" ixy="0.0" ixz="0.0" iyy="0.42175380379841093" iyz="0.0" izz="0.03636562499999999"/>
    </inertial>
  </link>
  <joint name="elbow_joint" type="revolute">
    <parent link="upper_arm_link"/>
    <child link="forearm_link"/>
    <origin rpy="0.0 0.0 0.0" xyz="0.0 -0.1719 0.612"/>
    <axis xyz="0 1 0"/>
    <limit effort="150.0" lower="-3.141592653589793" upper="3.141592653589793" velocity="3.15"/>
    <dynamics damping="0.0" friction="0.0"/>
  </joint>
  <link name="forearm_link">
    <visual>
      <geometry>
        <mesh filename="package://ur10/ur10/visual/forearm.dae"/>
      </geometry>
      <material name="LightGrey">
        <color rgba="0.7 0.7 0.7 1.0"/>
      </material>
    </visual>
    <collision>
      <geometry>
        <mesh filename="package://ur10/ur10/collision/forearm.stl"/>
      </geometry>
    </collision>
    <inertial>
      <mass value="3.87"/>
      <origin rpy="0 0 0" xyz="0.0 0.0 0.28615"/>
      <inertia ixx="0.11106969409710458" ixy="0.0" ixz="0.0" iyy="0.11106969409710458" iyz="0.0" izz="0.010884375"/>
    </inertial>
  </link>
  <joint name="wrist_1_joint" type="revolute">
    <parent link="forearm_link"/>
    <child link="wrist_1_link"/>
    <origin rpy="0.0 1.5707963267948966 0.0" xyz="0.0 0.0 0.5723"/>
    <axis xyz="0 1 0"/>
    <limit effort="54.0" lower="-6.283185307179586" upper="6.283185307179586" velocity="3.2"/>
    <dynamics damping="0.0" friction="0.0"/>
  </joint>
  <link name="wrist_1_link">
    <visual>
      <geometry>
        <mesh filename="package://ur10/ur10/visual/wrist1.dae"/>
      </geometry>
      <material name="LightGrey">
        <color rgba="0.7 0.7 0.7 1.0"/>
      </material>
    </visual>
    <collision>
      <geometry>
        <mesh filename="package://ur10/ur10/collision/wrist1.stl"/>
      </geometry>
    </collision>
    <inertial>
      <mass value="1.96"/>
      <origin rpy="0 0 0" xyz="0.0 0.1149 0.0"/>
      <inertia ixx="0.005108247956699999" ixy="0.0" ixz="0.0" iyy="0.005108247956699999" iyz="0.0" izz="0.005512499999999999"/>
    </inertial>
  </link>
  <joint name="wrist_2_joint" type="revolute">
    <parent link="wrist_1_link"/>
    <child link="wrist_2_link"/>
    <origin rpy="0.0 0.0 0.0" xyz="0.0 0.1149 0.0"/>
    <axis xyz="0 0 1"/>
    <limit effort="54.0" lower="-6.283185307179586" upper="6.283185307179586" velocity="3.2"/>
    <dynamics damping="0.0" friction="0.0"/>
  </joint>
  <link name="wrist_2_link">
    <visual>
      <geometry>
        <mesh filename="package://ur10/ur10/visual/wrist2.dae"/>
      </geometry>
      <material name="LightGrey">
        <color rgba="0.7 0.7 0.7 1.0"/>
      </material>
    </visual>
    <collision>
      <geometry>
        <mesh filename="package://ur10/ur10/collision/wrist2.stl"/>
      </geometry>
    </collision>
    <inertial>
      <mass value="1.96"/>
      <origin rpy="0 0 0" xyz="0.0 0.0 0.1157"/>
      <inertia ixx="0.005108247956699999" ixy="0.0" ixz="0.0" iyy="0.005108247956699999" iyz="0.0" izz="0.005512499999999999"/>
    </inertial>
  </link>
  <joint name="wrist_3_joint" type="revolute">
    <parent link="wrist_2_link"/>
    <child link="wrist_3_link"/>
    <origin rpy="0.0 0.0 0.0" xyz="0.0 0.0 0.1157"/>
    <axis xyz="0 1 0"/>
    <limit effort="54.0" lower="-6.283185307179586" upper="6.283185307179586" velocity="3.2"/>
    <dynamics damping="0.0" friction="0.0"/>
  </joint>
  <link name="wrist_3_link">
    <visual>
      <geometry>
        <mesh filename="package://ur10/ur10/visual/wrist3.dae"/>
      </geometry>
      <material name="LightGrey">
        <color rgba="0.7 0.7 0.7 1.0"/>
      </material>
    </visual>
    <collision>
      <geometry>
        <mesh filename="package://ur10/ur10/collision/wrist3.stl"/>
      </geometry>
    </collision>
    <inertial>
      <mass value="0.202"/>
      <origin rpy="1.5707963267948966 0 0" xyz="0.0 0.07695 0.0"/>
      <inertia ixx="0.00011792166116465" ixy="0.0" ixz="0.0" iyy="0.00011792166116465" iyz="0.0" izz="0.00020452200000000002"/>
    </inertial>
  </link>
  <transmission name="shoulder_pan_trans">
    <type>transmission_interface/SimpleTransmission</type>
    <joint name="shoulder_pan_joint">
      <hardwareInterface>hardware_interface/PositionJointInterface</hardwareInterface>
    </joint>
    <actuator name="shoulder_pan_motor">
      <mechanicalReduction>1</mechanicalReduction>
    </actuator>
  </transmission>
  <transmission name="shoulder_lift_trans">
    <type>transmission_interface/SimpleTransmission</type>
    <joint name="shoulder_lift_joint">
      <hardwareInterface>hardware_interface/PositionJointInterface</hardwareInterface>
    </joint>
    <actuator name="shoulder_lift_motor">
      <mechanicalReduction>1</mechanicalReduction>
    </actuator>
  </transmission>
  <transmission name="elbow_trans">
    <type>transmission_interface/SimpleTransmission</type>
    <joint name="elbow_joint">
      <hardwareInterface>hardware_interface/PositionJointInterface</hardwareInterface>
    </joint>
    <actuator name="elbow_motor">
      <mechanicalReduction>1</mechanicalReduction>
    </actuator>
  </transmission>
  <transmission name="wrist_1_trans">
    <type>transmission_interface/SimpleTransmission</type>
    <joint name="wrist_1_joint">
      <hardwareInterface>hardware_interface/PositionJointInterface</hardwareInterface>
    </joint>
    <actuator name="wrist_1_motor">
      <mechanicalReduction>1</mechanicalReduction>
    </actuator>
  </transmission>
  <transmission name="wrist_2_trans">
    <type>transmission_interface/SimpleTransmission</type>
    <joint name="wrist_2_joint">
      <hardwareInterface>hardware_interface/PositionJointInterface</hardwareInterface>
    </joint>
    <actuator name="wrist_2_motor">
      <mechanicalReduction>1</mechanicalReduction>
    </actuator>
  </transmission>
  <transmission name="wrist_3_trans">
    <type>transmission_interface/SimpleTransmission</type>
    <joint name="wrist_3_joint">
      <hardwareInterface>hardware_interface/PositionJointInterface</hardwareInterface>
    </joint>
    <actuator name="wrist_3_motor">
      <mechanicalReduction>1</mechanicalReduction>
    </actuator>
  </transmission>
  <gazebo reference="shoulder_link">
    <selfCollide>true</selfCollide>
  </gazebo>
  <gazebo reference="upper_arm_link">
    <selfCollide>true</selfCollide>
  </gazebo>
  <gazebo reference="forearm_link">
    <selfCollide>true</selfCollide>
  </gazebo>
  <gazebo reference="wrist_1_link">
    <selfCollide>true</selfCollide>
  </gazebo>
  <gazebo reference="wrist_3_link">
    <selfCollide>true</selfCollide>
  </gazebo>
  <gazebo reference="wrist_2_link">
    <selfCollide>true</selfCollide>
  </gazebo>
  <gazebo reference="ee_link">
    <selfCollide>true</selfCollide>
  </gazebo>
  <!-- ROS base_link to UR 'Base' Coordinates transform -->
  <!-- Frame coincident with all-zeros TCP on UR controller -->
  <link name="tool0">
    <inertial>
      <mass value="1e-3"/>
      <origin rpy="0 0 0" xyz="0.0 0.0 0.0"/>
      <inertia ixx="1e-5" ixy="0.0" ixz="0.0" iyy="1e-5" iyz="0.0" izz="1e-5"/>
    </inertial>
  </link>
  <joint name="wrist_3_link-tool0_fixed_joint" type="fixed">
    <origin rpy="-1.5707963267948966 0 0" xyz="0 0.0922 0"/>
    <parent link="wrist_3_link"/>
    <child link="tool0"/>
  </joint>
  <material name="black">
    <color rgba="0.0 0.0 0.0 1.0"/>
  </material>
  <material name="blue">
    <color rgba="0.0 0.0 0.8 1.0"/>
  </material>
  <material name="green">
    <color rgba="0.0 0.8 0.0 1.0"/>
  </material>
  <material name="grey">
    <color rgba="0.2 0.2 0.2 1.0"/>
  </material>
  <material name="orange">
      <color rgba="1.0 0.4235 0.0392 1.0"/>
  </material>
  <material name="brown">
      <color rgba="0.8706 0.8118 0.7647 1.0"/>
  </material>
  <material name="red">
    <color rgba="0.8 0.0 0.0 1.0"/>
  </material>
  <material name="white">
    <color rgba="1.0 1.0 1.0 1.0"/>
  </material>
  <!-- base -->
  <link name="rh_p12_rn_base">
    <collision>
      <origin xyz="0 0 0" rpy="0 0 0"/>
      <geometry>
        <mesh filename="package://ur10/robotis_rh_p12_rn/collision/base.stl" scale="0.001 0.001 0.001"/>
      </geometry>
    </collision>
    <visual>
      <origin xyz="0 0 0" rpy="0 0 0"/>
      <geometry>
        <mesh filename="package://ur10/robotis_rh_p12_rn/visual/base.stl" scale="0.001 0.001 0.001"/>
      </geometry>
      <material name="grey"/>
    </visual>
    <inertial>
      <origin xyz="0.000 0.000 0.032" rpy="0 0 0"/>
      <mass value="0.236"/>
      <!--<inertia ixx="0.00017" ixy="0.0" ixz="0.0" iyy="0.00011" iyz="0.0" izz="0.00017" />-->
      <!--<inertia ixx="1.0" ixy="0.0" ixz="0.0" iyy="1.0" iyz="0.0" izz="1.0" />-->
      <inertia ixx="0.001" ixy="0.0" ixz="0.0" iyy="0.001" iyz="0.0" izz="0.001" />
    </inertial>
  </link>
  <!-- Joint -->
  <joint name="rh_p12_rn" type="prismatic">
    <parent link="rh_p12_rn_base"/>
    <child link="rh_p12_rn_r1"/>
    <origin xyz="0.0 0.008 0.048" rpy="0 0 0"/>
    <axis xyz="0 -1 0"/>
    <limit velocity="6.5" effort="1000" lower="0.0" upper="0.053" />
    <dynamics damping="0.7"/>
  </joint>
  <!-- <joint name="rh_p12_rn" type="revolute">
    <parent link="rh_p12_rn_base"/>
    <child link="rh_p12_rn_r1"/>
    <origin xyz="0.0 0.008 0.048" rpy="0 0 0"/>
    <axis xyz="1 0 0"/>
    <limit velocity="6.5" effort="1000" lower="0.0" upper="1.115" />
    <dynamics damping="0.7"/>
  </joint> -->
  <gazebo reference="rh_p12_rn">
    <PID type="position">
      <p>1000.0</p>
      <i>0.0</i>
      <d>100.0</d>
    </PID>
  </gazebo>
  <transmission name="tran_r1">
    <type>transmission_interface/SimpleTransmission</type>
    <joint name="rh_p12_rn">
      <hardwareInterface>hardware_interface/PositionJointInterface</hardwareInterface>
    </joint>
    <actuator name="motor_r1">
      <hardwareInterface>hardware_interface/PositionJointInterface</hardwareInterface>
      <mechanicalReduction>1</mechanicalReduction>
    </actuator>
  </transmission>
  <!-- rh_p12_rn_r1 -->
  <link name="rh_p12_rn_r1">
    <collision>
      <origin xyz="0 0 0" rpy="0 0 0"/>
      <geometry>
        <mesh filename="package://ur10/robotis_rh_p12_rn/collision/r1.stl" scale="0.001 0.001 0.001"/>
      </geometry>
    </collision>
    <visual>
      <origin xyz="0 0 0" rpy="0 0 0"/>
      <geometry>
        <mesh filename="package://ur10/robotis_rh_p12_rn/visual/r1.stl" scale="0.001 0.001 0.001"/>
      </geometry>
      <material name="grey"/>
    </visual>
    <inertial>
      <origin xyz="0.000 0.034 0.004" rpy="0 0 0"/>
      <mass value="0.068"/>
      <!--<inertia ixx="0.00004" ixy="0.0" ixz="0.0" iyy="0.00002" iyz="-0.00001" izz="0.00002" />-->
      <!--<inertia ixx="1.0" ixy="0.0" ixz="0.0" iyy="1.0" iyz="0.0" izz="1.0" />-->
      <inertia ixx="0.001" ixy="0.0" ixz="0.0" iyy="0.001" iyz="0.0" izz="0.001" />
    </inertial>
  </link>
  <!-- Right Joint 2 -->
  <joint name="rh_r2" type="fixed">
    <parent link="rh_p12_rn_r1"/>
    <child link="rh_p12_rn_r2"/>
    <origin xyz="0.0 0.0493634 0.0285" rpy="0 0 0"/>
  </joint>
  <!-- <joint name="rh_r2" type="revolute">
    <parent link="rh_p12_rn_r1"/>
    <child link="rh_p12_rn_r2"/>
    <origin xyz="0.0 0.0493634 0.0285" rpy="0 0 0"/>
    <axis xyz="-1 0 0"/>
    <limit velocity="6.5" effort="1000" lower="0.0" upper="1.115" />
    <dynamics damping="0.7"/>
    <mimic joint="rh_p12_rn" multiplier="1" offset="0" />
  </joint>
  <gazebo reference="rh_r2">
    <PID type="position">
      <p>1000.0</p>
      <i>0.0</i>
      <d>100.0</d>
    </PID>
  </gazebo>
  <transmission name="tran_r2">
    <type>transmission_interface/SimpleTransmission</type>
    <joint name="rh_r2">
      <hardwareInterface>hardware_interface/PositionJointInterface</hardwareInterface>
    </joint>
    <actuator name="motor_r2">
      <hardwareInterface>hardware_interface/PositionJointInterface</hardwareInterface>
      <mechanicalReduction>1</mechanicalReduction>
    </actuator>
  </transmission> -->
  <!-- rh_p12_rn_r2 -->
  <link name="rh_p12_rn_r2">
    <collision>
      <origin xyz="0 0 0.012" rpy="0 0 0"/>
      <geometry>
        <mesh filename="package://ur10/robotis_rh_p12_rn/collision/r2.stl" scale="0.001 0.001 0.0015"/>
      </geometry>
    </collision>
    <visual>
      <origin xyz="0 0 0.012" rpy="0 0 0"/>
      <geometry>
        <mesh filename="package://ur10/robotis_rh_p12_rn/visual/r2.stl" scale="0.001 0.001 0.0015"/>
      </geometry>
      <material name="grey"/>
    </visual>
    <inertial>
      <origin xyz="0.000 0.006 0.011" rpy="0 0 0"/>
      <mass value="0.022"/>
      <!--<inertia ixx="0.0" ixy="0.0" ixz="0.0" iyy="0.00001" iyz="0.0" izz="0.0" />-->
      <!--<inertia ixx="1.0" ixy="0.0" ixz="0.0" iyy="1.0" iyz="0.0" izz="1.0" />-->
      <inertia ixx="0.001" ixy="0.0" ixz="0.0" iyy="0.001" iyz="0.0" izz="0.001" />
    </inertial>
    <contact>
      <friction_anchor/>
      <stiffness value="30000.0"/>
      <damping value="1000.0"/>
      <spinning_friction value="0.1"/>
      <lateral_friction value="1.0"/>
    </contact>
  </link>
  <!-- Left Joint 1 -->
  <joint name="rh_l1" type="prismatic">
    <parent link="rh_p12_rn_base"/>
    <child link="rh_p12_rn_l1"/>
    <origin xyz="0.0 -0.008 0.048" rpy="0 0 0"/>
    <axis xyz="0 1 0"/>
    <limit velocity="6.5" effort="1000" lower="0.0" upper="0.053" />
    <dynamics damping="0.7"/>
    <mimic joint="rh_p12_rn" multiplier="1" offset="0" />
  </joint>
  <!-- <joint name="rh_l1" type="revolute">
    <parent link="rh_p12_rn_base"/>
    <child link="rh_p12_rn_l1"/>
    <origin xyz="0.0 -0.008 0.048" rpy="0 0 0"/>
    <axis xyz="-1 0 0"/>
    <limit velocity="6.5" effort="1000" lower="0.0" upper="1.115" />
    <dynamics damping="0.7"/>
    <mimic joint="rh_p12_rn" multiplier="1" offset="0" />
  </joint> -->
  <gazebo reference="rh_l1">
    <PID type="position">
      <p>1000.0</p>
      <i>0.0</i>
      <d>100.0</d>
    </PID>
  </gazebo>
  <transmission name="tran_l1">
    <type>transmission_interface/SimpleTransmission</type>
    <joint name="rh_l1">
      <hardwareInterface>hardware_interface/PositionJointInterface</hardwareInterface>
    </joint>
    <actuator name="motor_l1">
      <hardwareInterface>hardware_interface/PositionJointInterface</hardwareInterface>
      <mechanicalReduction>1</mechanicalReduction>
    </actuator>
  </transmission>
  <!-- rh_p12_rn_l1 -->
  <link name="rh_p12_rn_l1">
    <collision>
      <origin xyz="0 0 0" rpy="0 0 0"/>
      <geometry>
        <mesh filename="package://ur10/robotis_rh_p12_rn/collision/l1.stl" scale="0.001 0.001 0.001"/>
      </geometry>
    </collision>
    <visual>
      <origin xyz="0 0 0" rpy="0 0 0"/>
      <geometry>
        <mesh filename="package://ur10/robotis_rh_p12_rn/visual/l1.stl" scale="0.001 0.001 0.001"/>
      </geometry>
      <material name="grey"/>
    </visual>
    <inertial>
      <origin xyz="0.000 -0.034 0.004" rpy="0 0 0"/>
      <mass value="0.068"/>
      <!--<inertia ixx="0.00004" ixy="0.0" ixz="0.0" iyy="0.00002" iyz="0.00001" izz="0.00002" />-->
      <!--<inertia ixx="1.0" ixy="0.0" ixz="0.0" iyy="1.0" iyz="0.0" izz="1.0" />-->
      <inertia ixx="0.001" ixy="0.0" ixz="0.0" iyy="0.001" iyz="0.0" izz="0.001" />
    </inertial>
  </link>
  <!-- Left Joint 2 -->
  <joint name="rh_l2" type="fixed">
    <parent link="rh_p12_rn_l1"/>
    <child link="rh_p12_rn_l2"/>
    <origin xyz="0.0 -0.0493634 0.0285" rpy="0 0 0"/>
  </joint>
  <!-- <joint name="rh_l2" type="revolute">
    <parent link="rh_p12_rn_l1"/>
    <child link="rh_p12_rn_l2"/>
    <origin xyz="0.0 -0.0493634 0.0285" rpy="0 0 0"/>
    <axis xyz="1 0 0"/>
    <limit velocity="6.5" effort="1000" lower="0.0" upper="1.115" />
    <dynamics damping="0.7"/>
    <mimic joint="rh_p12_rn" multiplier="1" offset="0" />
  </joint>
  <gazebo reference="rh_l2">
    <PID type="position">
      <p>1000.0</p>
      <i>0.0</i>
      <d>100.0</d>
    </PID>
  </gazebo>
  <transmission name="tran_l2">
    <type>transmission_interface/SimpleTransmission</type>
    <joint name="rh_l2">
      <hardwareInterface>hardware_interface/PositionJointInterface</hardwareInterface>
    </joint>
    <actuator name="motor_l2">
      <hardwareInterface>hardware_interface/PositionJointInterface</hardwareInterface>
      <mechanicalReduction>1</mechanicalReduction>
    </actuator>
  </transmission> -->
  <!-- rh_p12_rn_l2 -->
  <link name="rh_p12_rn_l2">
    <collision>
      <origin xyz="0 0 0.012" rpy="0 0 0"/>
      <geometry>
        <mesh filename="package://ur10/robotis_rh_p12_rn/collision/l2.stl" scale="0.001 0.001 0.0015"/>
      </geometry>
    </collision>
    <visual>
      <origin xyz="0 0 0.012" rpy="0 0 0"/>
      <geometry>
        <mesh filename="package://ur10/robotis_rh_p12_rn/visual/l2.stl" scale="0.001 0.001 0.0015"/>
      </geometry>
      <material name="grey"/>
    </visual>
    <inertial>
      <origin xyz="0.000 -0.006 0.011" rpy="0 0 0"/>
      <mass value="0.022"/>
      <!--<inertia ixx="0.0" ixy="0.0" ixz="0.0" iyy="0.00001" iyz="0.0" izz="0.0" />-->
      <!--<inertia ixx="1.0" ixy="0.0" ixz="0.0" iyy="1.0" iyz="0.0" izz="1.0" />-->
      <inertia ixx="0.001" ixy="0.0" ixz="0.0" iyy="0.001" iyz="0.0" izz="0.001" />
    </inertial>
    <contact>
      <friction_anchor/>
      <stiffness value="30000.0"/>
      <damping value="1000.0"/>
      <spinning_friction value="0.1"/>
      <lateral_friction value="1.0"/>
    </contact>
  </link>
  <!-- EE -->
  <joint name="ee_fixed_joint" type="fixed">
    <parent link="rh_p12_rn_base"/>
    <child link="ee_link"/>
    <origin rpy="0.0 0.0 0.0" xyz="0.0 0.0 0.135"/>
  </joint>
  <link name="ee_link">
    <inertial>
      <mass value="1e-3"/>
      <origin rpy="0 0 0" xyz="0.0 0.0 0.0"/>
      <inertia ixx="1e-5" ixy="0.0" ixz="0.0" iyy="1e-5" iyz="0.0" izz="1e-5"/>
    </inertial>
  </link>
  <joint name="tool0_rh_p12_rn_base" type="fixed">
    <origin rpy="0 0 0" xyz="0 0 0"/>
    <parent link="tool0"/>
    <child link="rh_p12_rn_base"/>
  </joint>
  <material name="aluminum">
    <color rgba="0.8 0.8 0.8 1"/>
  </material>
  <!-- camera body, with origin at bottom screw mount -->
  <joint name="d435_joint" type="fixed">
    <origin rpy="0 -1.57 0" xyz="-0.03 0 0.03"/>
    <parent link="rh_p12_rn_base"/>
    <child link="d435_bottom_screw_frame"/>
  </joint>
  <link name="d435_bottom_screw_frame">
    <inertial>
      <origin rpy="0 0 0" xyz="0 0 0"/>
      <mass value="0.001"/>
      <inertia ixx="1E-5" ixy="0" ixz="0" iyy="1E-5" iyz="-0" izz="1E-5"/>
    </inertial>
  </link>
  <joint name="d435_link_joint" type="fixed">
    <origin rpy="0 0 0" xyz="0 0.0175 0.0125"/>
    <parent link="d435_bottom_screw_frame"/>
    <child link="d435_link"/>
  </joint>
  <link name="d435_link">
    <visual>
      <origin rpy="1.5707963267948966 0 1.5707963267948966" xyz="0.0149 -0.0175 0"/>
      <geometry>
        <mesh filename="package://ur10/realsense2/visual/d435.dae"/>
      </geometry>
      <material name="aluminum"/>
    </visual>
    <collision>
      <origin rpy="0 0 0" xyz="0 -0.0175 0"/>
      <geometry>
        <box size="0.02505 0.09 0.025"/>
      </geometry>
    </collision>
    <inertial>
      <!-- The following are not reliable values, and should not be used for modeling -->
      <mass value="0.564"/>
      <origin xyz="0 0 0"/>
      <inertia ixx="0.003881243" ixy="0.0" ixz="0.0" iyy="0.000498940" iyz="0.0" izz="0.003879257"/>
    </inertial>
  </link>
  <!-- camera depth joints and links -->
  <joint name="d435_depth_joint" type="fixed">
    <origin rpy="0 0 0" xyz="0 0 0"/>
    <parent link="d435_link"/>
    <child link="d435_depth_frame"/>
  </joint>
  <link name="d435_depth_frame">
    <inertial>
      <origin rpy="0 0 0" xyz="0 0 0"/>
      <mass value="0.001"/>
      <inertia ixx="1E-5" ixy="0" ixz="0" iyy="1E-5" iyz="-0" izz="1E-5"/>
    </inertial>
  </link>
  <!-- camera color joints and links -->
  <joint name="d435_color_joint" type="fixed">
    <origin rpy="0 0 0" xyz="0 0.015 0"/>
    <parent link="d435_depth_frame"/>
    <child link="d435_color_frame"/>
  </joint>
  <link name="d435_color_frame">
    <inertial>
      <origin rpy="0 0 0" xyz="0 0 0"/>
      <mass value="0.001"/>
      <inertia ixx="1E-5" ixy="0" ixz="0" iyy="1E-5" iyz="-0" izz="1E-5"/>
    </inertial>
  </link>
  <!--Klampt-->
  <!--Somehow the visual doesn't work for UR10 (maybe because of the dae?)-->
  <!--<klampt package_root=".." flip_yz="1" use_vis_geom="1" freeze_root_link="1" default_acc_max="4">-->
  <klampt package_root=".." freeze_root_link="1" default_acc_max="4">
    <link name="tool0" physical="0" />
    <link name="ee_link" physical="0" />
    <!-- <link name="d435_bottom_screw_frame" physical="0" /> -->
    <link name="d435_depth_frame" physical="0" />
    <link name="d435_color_frame" physical="0" />
    <!---->
    <link name="shoulder_link" servoP="200" servoI="0" servoD="10"/>
    <link name="upper_arm_link" servoP="200" servoI="0" servoD="10"/>
    <link name="forearm_link" servoP="200" servoI="0" servoD="10"/>
    <link name="wrist_1_link" servoP="200" servoI="0" servoD="10"/>
    <link name="wrist_2_link" servoP="200" servoI="0" servoD="10"/>
    <link name="wrist_3_link" servoP="200" servoI="0" servoD="10"/>
    <link name="rh_p12_rn_r1" servoP="200" servoI="0" servoD="10"/>
    <link name="rh_p12_rn_l1" servoP="200" servoI="0" servoD="10"/>
    <!---->
    <noselfcollision pairs="base_link shoulder_link" />
    <noselfcollision group1="upper_arm_link" group2="shoulder_link forearm_link" />
    <noselfcollision group1="wrist_1_link" group2="upper_arm_link wrist_2_link wrist_3_link" />
    <noselfcollision group1="wrist_3_link" group2="wrist_2_link rh_p12_rn_base" />
    <noselfcollision group1="ee_link" group2="wrist_1_link wrist_2_link wrist_3_link tool0 rh_p12_rn_base" />
    <noselfcollision group1="tool0" group2="wrist_1_link wrist_2_link wrist_3_link rh_p12_rn_base" />
    <noselfcollision group1="rh_p12_rn_base" group2="rh_p12_rn_r1 rh_p12_rn_r2 rh_p12_rn_l1 rh_p12_rn_l2" />
    <noselfcollision group1="rh_p12_rn_r1" group2="rh_p12_rn_r2 rh_p12_rn_l1 rh_p12_rn_l2" />
    <noselfcollision group1="rh_p12_rn_l1" group2="rh_p12_rn_r2 rh_p12_rn_l2" />
    <noselfcollision group1="rh_p12_rn_l2" group2="rh_p12_rn_r2" />
  </klampt>
</robot>
